[2025-09-19T09:55:48.646+0000] {taskinstance.py:1956} INFO - Dependencies all met for dep_context=non-requeueable deps ti=<TaskInstance: crypto_data_generator.generate_and_upload_crypto_data scheduled__2025-09-19T08:00:00+00:00 [queued]>
[2025-09-19T09:55:48.660+0000] {taskinstance.py:1956} INFO - Dependencies all met for dep_context=requeueable deps ti=<TaskInstance: crypto_data_generator.generate_and_upload_crypto_data scheduled__2025-09-19T08:00:00+00:00 [queued]>
[2025-09-19T09:55:48.661+0000] {taskinstance.py:2170} INFO - Starting attempt 1 of 3
[2025-09-19T09:55:48.684+0000] {taskinstance.py:2191} INFO - Executing <Task(PythonOperator): generate_and_upload_crypto_data> on 2025-09-19 08:00:00+00:00
[2025-09-19T09:55:48.694+0000] {standard_task_runner.py:60} INFO - Started process 1486 to run task
[2025-09-19T09:55:48.700+0000] {standard_task_runner.py:87} INFO - Running: ['***', 'tasks', 'run', 'crypto_data_generator', 'generate_and_upload_crypto_data', 'scheduled__2025-09-19T08:00:00+00:00', '--job-id', '10', '--raw', '--subdir', 'DAGS_FOLDER/crypto_data_generator_dag.py', '--cfg-path', '/tmp/tmp1omzrs7u']
[2025-09-19T09:55:48.703+0000] {standard_task_runner.py:88} INFO - Job 10: Subtask generate_and_upload_crypto_data
[2025-09-19T09:55:48.786+0000] {task_command.py:423} INFO - Running <TaskInstance: crypto_data_generator.generate_and_upload_crypto_data scheduled__2025-09-19T08:00:00+00:00 [running]> on host 024162058ce7
[2025-09-19T09:55:48.911+0000] {taskinstance.py:2480} INFO - Exporting env vars: AIRFLOW_CTX_DAG_OWNER='data-team' AIRFLOW_CTX_DAG_ID='crypto_data_generator' AIRFLOW_CTX_TASK_ID='generate_and_upload_crypto_data' AIRFLOW_CTX_EXECUTION_DATE='2025-09-19T08:00:00+00:00' AIRFLOW_CTX_TRY_NUMBER='1' AIRFLOW_CTX_DAG_RUN_ID='scheduled__2025-09-19T08:00:00+00:00'
[2025-09-19T09:55:48.919+0000] {taskinstance.py:2698} ERROR - Task failed with exception
Traceback (most recent call last):
  File "/home/airflow/.local/lib/python3.8/site-packages/airflow/models/taskinstance.py", line 433, in _execute_task
    result = execute_callable(context=context, **execute_callable_kwargs)
  File "/home/airflow/.local/lib/python3.8/site-packages/airflow/operators/python.py", line 199, in execute
    return_value = self.execute_callable()
  File "/home/airflow/.local/lib/python3.8/site-packages/airflow/operators/python.py", line 216, in execute_callable
    return self.python_callable(*self.op_args, **self.op_kwargs)
  File "/opt/airflow/dags/crypto_data_generator_dag.py", line 57, in generate_and_upload_data
    from scripts.generate_data import generate_csv_for_hour
ModuleNotFoundError: No module named 'scripts.generate_data'
[2025-09-19T09:55:48.942+0000] {taskinstance.py:1138} INFO - Marking task as UP_FOR_RETRY. dag_id=crypto_data_generator, task_id=generate_and_upload_crypto_data, execution_date=20250919T080000, start_date=20250919T095548, end_date=20250919T095548
[2025-09-19T09:55:48.966+0000] {standard_task_runner.py:107} ERROR - Failed to execute job 10 for task generate_and_upload_crypto_data (No module named 'scripts.generate_data'; 1486)
[2025-09-19T09:55:48.994+0000] {local_task_job_runner.py:234} INFO - Task exited with return code 1
[2025-09-19T09:55:49.021+0000] {taskinstance.py:3280} INFO - 0 downstream tasks scheduled from follow-on schedule check
