[2025-09-19T13:48:16.804+0000] {taskinstance.py:1956} INFO - Dependencies all met for dep_context=non-requeueable deps ti=<TaskInstance: crypto_etl_main.check_new_files scheduled__2025-09-19T13:30:00+00:00 [queued]>
[2025-09-19T13:48:16.823+0000] {taskinstance.py:1956} INFO - Dependencies all met for dep_context=requeueable deps ti=<TaskInstance: crypto_etl_main.check_new_files scheduled__2025-09-19T13:30:00+00:00 [queued]>
[2025-09-19T13:48:16.824+0000] {taskinstance.py:2170} INFO - Starting attempt 1 of 2
[2025-09-19T13:48:16.850+0000] {taskinstance.py:2191} INFO - Executing <Task(BranchPythonOperator): check_new_files> on 2025-09-19 13:30:00+00:00
[2025-09-19T13:48:16.860+0000] {standard_task_runner.py:60} INFO - Started process 430 to run task
[2025-09-19T13:48:16.867+0000] {standard_task_runner.py:87} INFO - Running: ['***', 'tasks', 'run', 'crypto_etl_main', 'check_new_files', 'scheduled__2025-09-19T13:30:00+00:00', '--job-id', '71', '--raw', '--subdir', 'DAGS_FOLDER/crypto_etl_dag.py', '--cfg-path', '/tmp/tmpcepy3q0p']
[2025-09-19T13:48:16.872+0000] {standard_task_runner.py:88} INFO - Job 71: Subtask check_new_files
[2025-09-19T13:48:16.958+0000] {task_command.py:423} INFO - Running <TaskInstance: crypto_etl_main.check_new_files scheduled__2025-09-19T13:30:00+00:00 [running]> on host ed735ff6f76b
[2025-09-19T13:48:17.084+0000] {taskinstance.py:2480} INFO - Exporting env vars: AIRFLOW_CTX_DAG_OWNER='data-team' AIRFLOW_CTX_DAG_ID='crypto_etl_main' AIRFLOW_CTX_TASK_ID='check_new_files' AIRFLOW_CTX_EXECUTION_DATE='2025-09-19T13:30:00+00:00' AIRFLOW_CTX_TRY_NUMBER='1' AIRFLOW_CTX_DAG_RUN_ID='scheduled__2025-09-19T13:30:00+00:00'
[2025-09-19T13:48:17.283+0000] {log.py:232} WARNING - [2025-09-19 13:48:17,282] INFO - crypto_etl - Listing files from bucket crypto-data with prefix 'raw-data/'
[2025-09-19T13:48:17.282+0000] {extract.py:23} INFO - Listing files from bucket crypto-data with prefix 'raw-data/'
[2025-09-19T13:48:17.297+0000] {log.py:232} WARNING - [2025-09-19 13:48:17,296] ERROR - crypto_etl - Failed to list objects: S3 operation failed; code: SignatureDoesNotMatch, message: The request signature we calculated does not match the signature you provided. Check your key and signing method., resource: /crypto-data, request_id: 1866B329F351D9BB, host_id: dd9025bab4ad464b049177c95eb6ebf374d3b3fd1af9251148b658df7ac2e3e8, bucket_name: crypto-data
[2025-09-19T13:48:17.296+0000] {extract.py:30} ERROR - Failed to list objects: S3 operation failed; code: SignatureDoesNotMatch, message: The request signature we calculated does not match the signature you provided. Check your key and signing method., resource: /crypto-data, request_id: 1866B329F351D9BB, host_id: dd9025bab4ad464b049177c95eb6ebf374d3b3fd1af9251148b658df7ac2e3e8, bucket_name: crypto-data
[2025-09-19T13:48:17.302+0000] {taskinstance.py:2698} ERROR - Task failed with exception
Traceback (most recent call last):
  File "/home/airflow/.local/lib/python3.8/site-packages/airflow/models/taskinstance.py", line 433, in _execute_task
    result = execute_callable(context=context, **execute_callable_kwargs)
  File "/home/airflow/.local/lib/python3.8/site-packages/airflow/operators/python.py", line 233, in execute
    return self.do_branch(context, super().execute(context))
  File "/home/airflow/.local/lib/python3.8/site-packages/airflow/operators/python.py", line 199, in execute
    return_value = self.execute_callable()
  File "/home/airflow/.local/lib/python3.8/site-packages/airflow/operators/python.py", line 216, in execute_callable
    return self.python_callable(*self.op_args, **self.op_kwargs)
  File "/opt/airflow/dags/crypto_etl_dag.py", line 45, in check_new_files
    unprocessed_files = processor.get_unprocessed_files(all_files)
  File "/opt/airflow/dags/etl/file_processor.py", line 16, in get_unprocessed_files
    conn = psycopg2.connect(self.db_conn)
  File "/home/airflow/.local/lib/python3.8/site-packages/psycopg2/__init__.py", line 122, in connect
    conn = _connect(dsn, connection_factory=connection_factory, **kwasync)
psycopg2.OperationalError: connection to server at "localhost" (::1), port 5433 failed: Connection refused
	Is the server running on that host and accepting TCP/IP connections?
connection to server at "localhost" (127.0.0.1), port 5433 failed: Connection refused
	Is the server running on that host and accepting TCP/IP connections?

[2025-09-19T13:48:17.330+0000] {taskinstance.py:1138} INFO - Marking task as UP_FOR_RETRY. dag_id=crypto_etl_main, task_id=check_new_files, execution_date=20250919T133000, start_date=20250919T134816, end_date=20250919T134817
[2025-09-19T13:48:17.349+0000] {standard_task_runner.py:107} ERROR - Failed to execute job 71 for task check_new_files (connection to server at "localhost" (::1), port 5433 failed: Connection refused
	Is the server running on that host and accepting TCP/IP connections?
connection to server at "localhost" (127.0.0.1), port 5433 failed: Connection refused
	Is the server running on that host and accepting TCP/IP connections?
; 430)
[2025-09-19T13:48:17.402+0000] {local_task_job_runner.py:234} INFO - Task exited with return code 1
[2025-09-19T13:48:17.450+0000] {taskinstance.py:3280} INFO - 0 downstream tasks scheduled from follow-on schedule check
