[2025-09-19T10:05:59.458+0000] {taskinstance.py:1956} INFO - Dependencies all met for dep_context=non-requeueable deps ti=<TaskInstance: crypto_data_generator.generate_and_upload_crypto_data scheduled__2025-09-19T09:00:00+00:00 [queued]>
[2025-09-19T10:05:59.472+0000] {taskinstance.py:1956} INFO - Dependencies all met for dep_context=requeueable deps ti=<TaskInstance: crypto_data_generator.generate_and_upload_crypto_data scheduled__2025-09-19T09:00:00+00:00 [queued]>
[2025-09-19T10:05:59.473+0000] {taskinstance.py:2170} INFO - Starting attempt 1 of 3
[2025-09-19T10:05:59.500+0000] {taskinstance.py:2191} INFO - Executing <Task(PythonOperator): generate_and_upload_crypto_data> on 2025-09-19 09:00:00+00:00
[2025-09-19T10:05:59.509+0000] {standard_task_runner.py:60} INFO - Started process 1639 to run task
[2025-09-19T10:05:59.514+0000] {standard_task_runner.py:87} INFO - Running: ['***', 'tasks', 'run', 'crypto_data_generator', 'generate_and_upload_crypto_data', 'scheduled__2025-09-19T09:00:00+00:00', '--job-id', '13', '--raw', '--subdir', 'DAGS_FOLDER/crypto_data_generator_dag.py', '--cfg-path', '/tmp/tmp90eb53q2']
[2025-09-19T10:05:59.517+0000] {standard_task_runner.py:88} INFO - Job 13: Subtask generate_and_upload_crypto_data
[2025-09-19T10:05:59.603+0000] {task_command.py:423} INFO - Running <TaskInstance: crypto_data_generator.generate_and_upload_crypto_data scheduled__2025-09-19T09:00:00+00:00 [running]> on host 024162058ce7
[2025-09-19T10:05:59.724+0000] {taskinstance.py:2480} INFO - Exporting env vars: AIRFLOW_CTX_DAG_OWNER='data-team' AIRFLOW_CTX_DAG_ID='crypto_data_generator' AIRFLOW_CTX_TASK_ID='generate_and_upload_crypto_data' AIRFLOW_CTX_EXECUTION_DATE='2025-09-19T09:00:00+00:00' AIRFLOW_CTX_TRY_NUMBER='1' AIRFLOW_CTX_DAG_RUN_ID='scheduled__2025-09-19T09:00:00+00:00'
[2025-09-19T10:05:59.730+0000] {taskinstance.py:2698} ERROR - Task failed with exception
Traceback (most recent call last):
  File "/home/airflow/.local/lib/python3.8/site-packages/airflow/models/taskinstance.py", line 433, in _execute_task
    result = execute_callable(context=context, **execute_callable_kwargs)
  File "/home/airflow/.local/lib/python3.8/site-packages/airflow/operators/python.py", line 199, in execute
    return_value = self.execute_callable()
  File "/home/airflow/.local/lib/python3.8/site-packages/airflow/operators/python.py", line 216, in execute_callable
    return self.python_callable(*self.op_args, **self.op_kwargs)
  File "/opt/airflow/dags/crypto_data_generator_dag.py", line 57, in generate_and_upload_data
    from scripts.generate_data import generate_csv_for_hour
ModuleNotFoundError: No module named 'scripts.generate_data'
[2025-09-19T10:05:59.750+0000] {taskinstance.py:1138} INFO - Marking task as UP_FOR_RETRY. dag_id=crypto_data_generator, task_id=generate_and_upload_crypto_data, execution_date=20250919T090000, start_date=20250919T100559, end_date=20250919T100559
[2025-09-19T10:05:59.775+0000] {standard_task_runner.py:107} ERROR - Failed to execute job 13 for task generate_and_upload_crypto_data (No module named 'scripts.generate_data'; 1639)
[2025-09-19T10:05:59.808+0000] {local_task_job_runner.py:234} INFO - Task exited with return code 1
[2025-09-19T10:05:59.837+0000] {taskinstance.py:3280} INFO - 0 downstream tasks scheduled from follow-on schedule check
