[2025-09-19T15:09:02.950+0000] {taskinstance.py:1956} INFO - Dependencies all met for dep_context=non-requeueable deps ti=<TaskInstance: crypto_etl_main.transform__and_load_data manual__2025-09-19T15:08:46.846243+00:00 [queued]>
[2025-09-19T15:09:02.965+0000] {taskinstance.py:1956} INFO - Dependencies all met for dep_context=requeueable deps ti=<TaskInstance: crypto_etl_main.transform__and_load_data manual__2025-09-19T15:08:46.846243+00:00 [queued]>
[2025-09-19T15:09:02.966+0000] {taskinstance.py:2170} INFO - Starting attempt 1 of 2
[2025-09-19T15:09:02.997+0000] {taskinstance.py:2191} INFO - Executing <Task(PythonOperator): transform__and_load_data> on 2025-09-19 15:08:46.846243+00:00
[2025-09-19T15:09:03.006+0000] {standard_task_runner.py:60} INFO - Started process 1679 to run task
[2025-09-19T15:09:03.013+0000] {standard_task_runner.py:87} INFO - Running: ['***', 'tasks', 'run', 'crypto_etl_main', 'transform__and_load_data', 'manual__2025-09-19T15:08:46.846243+00:00', '--job-id', '109', '--raw', '--subdir', 'DAGS_FOLDER/crypto_etl_dag.py', '--cfg-path', '/tmp/tmpsr1nl48_']
[2025-09-19T15:09:03.017+0000] {standard_task_runner.py:88} INFO - Job 109: Subtask transform__and_load_data
[2025-09-19T15:09:03.098+0000] {task_command.py:423} INFO - Running <TaskInstance: crypto_etl_main.transform__and_load_data manual__2025-09-19T15:08:46.846243+00:00 [running]> on host ed735ff6f76b
[2025-09-19T15:09:03.233+0000] {taskinstance.py:2480} INFO - Exporting env vars: AIRFLOW_CTX_DAG_OWNER='data-team' AIRFLOW_CTX_DAG_ID='crypto_etl_main' AIRFLOW_CTX_TASK_ID='transform__and_load_data' AIRFLOW_CTX_EXECUTION_DATE='2025-09-19T15:08:46.846243+00:00' AIRFLOW_CTX_TRY_NUMBER='1' AIRFLOW_CTX_DAG_RUN_ID='manual__2025-09-19T15:08:46.846243+00:00'
[2025-09-19T15:09:03.407+0000] {log.py:232} WARNING - [2025-09-19 15:09:03,404] INFO - crypto_etl - Starting data transformation...
[2025-09-19T15:09:03.404+0000] {transform.py:27} INFO - Starting data transformation...
[2025-09-19T15:09:03.413+0000] {log.py:232} WARNING - [2025-09-19 15:09:03,412] INFO - crypto_etl - Adding derived metrics...
[2025-09-19T15:09:03.412+0000] {transform.py:14} INFO - Adding derived metrics...
[2025-09-19T15:09:03.495+0000] {log.py:232} WARNING - [2025-09-19 15:09:03,494] INFO - crypto_etl - Data transformation complete
[2025-09-19T15:09:03.494+0000] {transform.py:32} INFO - Data transformation complete
[2025-09-19T15:09:03.508+0000] {log.py:232} WARNING - [2025-09-19 15:09:03,508] ERROR - crypto_etl - Marked raw-data/2025/09/19/16/crypto_data_20250919_16.csv as failed: Transform/load error: connection to server at "localhost" (::1), port 5433 failed: Connection refused
	Is the server running on that host and accepting TCP/IP connections?
connection to server at "localhost" (127.0.0.1), port 5433 failed: Connection refused
	Is the server running on that host and accepting TCP/IP connections?
[2025-09-19T15:09:03.508+0000] {file_processor.py:78} ERROR - Marked raw-data/2025/09/19/16/crypto_data_20250919_16.csv as failed: Transform/load error: connection to server at "localhost" (::1), port 5433 failed: Connection refused
	Is the server running on that host and accepting TCP/IP connections?
connection to server at "localhost" (127.0.0.1), port 5433 failed: Connection refused
	Is the server running on that host and accepting TCP/IP connections?

[2025-09-19T15:09:03.510+0000] {logging_mixin.py:188} INFO - âœ— Failed to process: raw-data/2025/09/19/16/crypto_data_20250919_16.csv - connection to server at "localhost" (::1), port 5433 failed: Connection refused
	Is the server running on that host and accepting TCP/IP connections?
connection to server at "localhost" (127.0.0.1), port 5433 failed: Connection refused
	Is the server running on that host and accepting TCP/IP connections?
[2025-09-19T15:09:03.562+0000] {python.py:201} INFO - Done. Returned value was: Processed 0 files successfully, 0 total records
[2025-09-19T15:09:03.593+0000] {taskinstance.py:1138} INFO - Marking task as SUCCESS. dag_id=crypto_etl_main, task_id=transform__and_load_data, execution_date=20250919T150846, start_date=20250919T150902, end_date=20250919T150903
[2025-09-19T15:09:03.626+0000] {local_task_job_runner.py:234} INFO - Task exited with return code 0
[2025-09-19T15:09:03.669+0000] {taskinstance.py:3280} INFO - 1 downstream tasks scheduled from follow-on schedule check
