[2025-09-19T10:54:29.990+0000] {taskinstance.py:1956} INFO - Dependencies all met for dep_context=non-requeueable deps ti=<TaskInstance: crypto_data_generator.generate_and_upload_crypto_data manual__2025-09-19T10:54:27.223071+00:00 [queued]>
[2025-09-19T10:54:30.007+0000] {taskinstance.py:1956} INFO - Dependencies all met for dep_context=requeueable deps ti=<TaskInstance: crypto_data_generator.generate_and_upload_crypto_data manual__2025-09-19T10:54:27.223071+00:00 [queued]>
[2025-09-19T10:54:30.008+0000] {taskinstance.py:2170} INFO - Starting attempt 1 of 3
[2025-09-19T10:54:30.036+0000] {taskinstance.py:2191} INFO - Executing <Task(PythonOperator): generate_and_upload_crypto_data> on 2025-09-19 10:54:27.223071+00:00
[2025-09-19T10:54:30.046+0000] {standard_task_runner.py:60} INFO - Started process 186 to run task
[2025-09-19T10:54:30.052+0000] {standard_task_runner.py:87} INFO - Running: ['***', 'tasks', 'run', 'crypto_data_generator', 'generate_and_upload_crypto_data', 'manual__2025-09-19T10:54:27.223071+00:00', '--job-id', '25', '--raw', '--subdir', 'DAGS_FOLDER/crypto_data_generator_dag.py', '--cfg-path', '/tmp/tmpklpmvlbr']
[2025-09-19T10:54:30.055+0000] {standard_task_runner.py:88} INFO - Job 25: Subtask generate_and_upload_crypto_data
[2025-09-19T10:54:30.153+0000] {task_command.py:423} INFO - Running <TaskInstance: crypto_data_generator.generate_and_upload_crypto_data manual__2025-09-19T10:54:27.223071+00:00 [running]> on host 72fd812e8415
[2025-09-19T10:54:30.368+0000] {taskinstance.py:2480} INFO - Exporting env vars: AIRFLOW_CTX_DAG_OWNER='data-team' AIRFLOW_CTX_DAG_ID='crypto_data_generator' AIRFLOW_CTX_TASK_ID='generate_and_upload_crypto_data' AIRFLOW_CTX_EXECUTION_DATE='2025-09-19T10:54:27.223071+00:00' AIRFLOW_CTX_TRY_NUMBER='1' AIRFLOW_CTX_DAG_RUN_ID='manual__2025-09-19T10:54:27.223071+00:00'
[2025-09-19T10:54:30.372+0000] {warnings.py:109} WARNING - /home/***/.local/lib/python3.8/site-packages/***/utils/context.py:315: AirflowContextDeprecationWarning: Accessing 'execution_date' from the template is deprecated and will be removed in a future version. Please use 'data_interval_start' or 'logical_date' instead.
  warnings.warn(_create_deprecation_warning(k, replacements))

[2025-09-19T10:54:30.374+0000] {logging_mixin.py:188} INFO - Generated /tmp/crypto_data_20250919_10.csv
[2025-09-19T10:54:30.381+0000] {connectionpool.py:824} WARNING - Retrying (Retry(total=4, connect=None, read=None, redirect=None, status=None)) after connection broken by 'NewConnectionError('<urllib3.connection.HTTPConnection object at 0x7f91e679fd00>: Failed to establish a new connection: [Errno 111] Connection refused')': /crypto-data?location=
[2025-09-19T10:54:30.783+0000] {connectionpool.py:824} WARNING - Retrying (Retry(total=3, connect=None, read=None, redirect=None, status=None)) after connection broken by 'NewConnectionError('<urllib3.connection.HTTPConnection object at 0x7f91e679ff40>: Failed to establish a new connection: [Errno 111] Connection refused')': /crypto-data?location=
[2025-09-19T10:54:31.586+0000] {connectionpool.py:824} WARNING - Retrying (Retry(total=2, connect=None, read=None, redirect=None, status=None)) after connection broken by 'NewConnectionError('<urllib3.connection.HTTPConnection object at 0x7f91e67ad190>: Failed to establish a new connection: [Errno 111] Connection refused')': /crypto-data?location=
[2025-09-19T10:54:33.190+0000] {connectionpool.py:824} WARNING - Retrying (Retry(total=1, connect=None, read=None, redirect=None, status=None)) after connection broken by 'NewConnectionError('<urllib3.connection.HTTPConnection object at 0x7f91e67ad5b0>: Failed to establish a new connection: [Errno 111] Connection refused')': /crypto-data?location=
[2025-09-19T10:54:36.397+0000] {connectionpool.py:824} WARNING - Retrying (Retry(total=0, connect=None, read=None, redirect=None, status=None)) after connection broken by 'NewConnectionError('<urllib3.connection.HTTPConnection object at 0x7f91e67ad850>: Failed to establish a new connection: [Errno 111] Connection refused')': /crypto-data?location=
[2025-09-19T10:54:36.400+0000] {logging_mixin.py:188} INFO - Failed to upload /tmp/crypto_data_20250919_10.csv: HTTPConnectionPool(host='localhost', port=9000): Max retries exceeded with url: /crypto-data?location= (Caused by NewConnectionError('<urllib3.connection.HTTPConnection object at 0x7f91e67ada60>: Failed to establish a new connection: [Errno 111] Connection refused'))
[2025-09-19T10:54:36.402+0000] {taskinstance.py:2698} ERROR - Task failed with exception
Traceback (most recent call last):
  File "/home/airflow/.local/lib/python3.8/site-packages/urllib3/connection.py", line 174, in _new_conn
    conn = connection.create_connection(
  File "/home/airflow/.local/lib/python3.8/site-packages/urllib3/util/connection.py", line 95, in create_connection
    raise err
  File "/home/airflow/.local/lib/python3.8/site-packages/urllib3/util/connection.py", line 85, in create_connection
    sock.connect(sa)
ConnectionRefusedError: [Errno 111] Connection refused

During handling of the above exception, another exception occurred:

Traceback (most recent call last):
  File "/home/airflow/.local/lib/python3.8/site-packages/urllib3/connectionpool.py", line 715, in urlopen
    httplib_response = self._make_request(
  File "/home/airflow/.local/lib/python3.8/site-packages/urllib3/connectionpool.py", line 416, in _make_request
    conn.request(method, url, **httplib_request_kw)
  File "/home/airflow/.local/lib/python3.8/site-packages/urllib3/connection.py", line 244, in request
    super(HTTPConnection, self).request(method, url, body=body, headers=headers)
  File "/usr/local/lib/python3.8/http/client.py", line 1256, in request
    self._send_request(method, url, body, headers, encode_chunked)
  File "/usr/local/lib/python3.8/http/client.py", line 1302, in _send_request
    self.endheaders(body, encode_chunked=encode_chunked)
  File "/usr/local/lib/python3.8/http/client.py", line 1251, in endheaders
    self._send_output(message_body, encode_chunked=encode_chunked)
  File "/usr/local/lib/python3.8/http/client.py", line 1011, in _send_output
    self.send(msg)
  File "/usr/local/lib/python3.8/http/client.py", line 951, in send
    self.connect()
  File "/home/airflow/.local/lib/python3.8/site-packages/urllib3/connection.py", line 205, in connect
    conn = self._new_conn()
  File "/home/airflow/.local/lib/python3.8/site-packages/urllib3/connection.py", line 186, in _new_conn
    raise NewConnectionError(
urllib3.exceptions.NewConnectionError: <urllib3.connection.HTTPConnection object at 0x7f91e67ada60>: Failed to establish a new connection: [Errno 111] Connection refused

During handling of the above exception, another exception occurred:

Traceback (most recent call last):
  File "/home/airflow/.local/lib/python3.8/site-packages/airflow/models/taskinstance.py", line 433, in _execute_task
    result = execute_callable(context=context, **execute_callable_kwargs)
  File "/home/airflow/.local/lib/python3.8/site-packages/airflow/operators/python.py", line 199, in execute
    return_value = self.execute_callable()
  File "/home/airflow/.local/lib/python3.8/site-packages/airflow/operators/python.py", line 216, in execute_callable
    return self.python_callable(*self.op_args, **self.op_kwargs)
  File "/opt/airflow/dags/crypto_data_generator_dag.py", line 69, in generate_and_upload_data
    upload_to_organized_path(local_temp_path, f"{folder_path}/{filename}")
  File "/opt/airflow/dags/crypto_data_generator_dag.py", line 47, in upload_to_organized_path
    if not client.bucket_exists(bucket_name):
  File "/home/airflow/.local/lib/python3.8/site-packages/minio/api.py", line 696, in bucket_exists
    self._execute("HEAD", bucket_name)
  File "/home/airflow/.local/lib/python3.8/site-packages/minio/api.py", line 437, in _execute
    region = self._get_region(bucket_name)
  File "/home/airflow/.local/lib/python3.8/site-packages/minio/api.py", line 494, in _get_region
    response = self._url_open(
  File "/home/airflow/.local/lib/python3.8/site-packages/minio/api.py", line 302, in _url_open
    response = self._http.urlopen(
  File "/home/airflow/.local/lib/python3.8/site-packages/urllib3/poolmanager.py", line 376, in urlopen
    response = conn.urlopen(method, u.request_uri, **kw)
  File "/home/airflow/.local/lib/python3.8/site-packages/urllib3/connectionpool.py", line 827, in urlopen
    return self.urlopen(
  File "/home/airflow/.local/lib/python3.8/site-packages/urllib3/connectionpool.py", line 827, in urlopen
    return self.urlopen(
  File "/home/airflow/.local/lib/python3.8/site-packages/urllib3/connectionpool.py", line 827, in urlopen
    return self.urlopen(
  [Previous line repeated 2 more times]
  File "/home/airflow/.local/lib/python3.8/site-packages/urllib3/connectionpool.py", line 799, in urlopen
    retries = retries.increment(
  File "/home/airflow/.local/lib/python3.8/site-packages/urllib3/util/retry.py", line 592, in increment
    raise MaxRetryError(_pool, url, error or ResponseError(cause))
urllib3.exceptions.MaxRetryError: HTTPConnectionPool(host='localhost', port=9000): Max retries exceeded with url: /crypto-data?location= (Caused by NewConnectionError('<urllib3.connection.HTTPConnection object at 0x7f91e67ada60>: Failed to establish a new connection: [Errno 111] Connection refused'))
[2025-09-19T10:54:36.458+0000] {taskinstance.py:1138} INFO - Marking task as UP_FOR_RETRY. dag_id=crypto_data_generator, task_id=generate_and_upload_crypto_data, execution_date=20250919T105427, start_date=20250919T105429, end_date=20250919T105436
[2025-09-19T10:54:36.486+0000] {standard_task_runner.py:107} ERROR - Failed to execute job 25 for task generate_and_upload_crypto_data (HTTPConnectionPool(host='localhost', port=9000): Max retries exceeded with url: /crypto-data?location= (Caused by NewConnectionError('<urllib3.connection.HTTPConnection object at 0x7f91e67ada60>: Failed to establish a new connection: [Errno 111] Connection refused')); 186)
[2025-09-19T10:54:36.512+0000] {local_task_job_runner.py:234} INFO - Task exited with return code 1
[2025-09-19T10:54:36.538+0000] {taskinstance.py:3280} INFO - 0 downstream tasks scheduled from follow-on schedule check
