[2025-09-19T14:54:00.362+0000] {taskinstance.py:1956} INFO - Dependencies all met for dep_context=non-requeueable deps ti=<TaskInstance: crypto_etl_main.transform_data manual__2025-09-19T14:53:41.738222+00:00 [queued]>
[2025-09-19T14:54:00.380+0000] {taskinstance.py:1956} INFO - Dependencies all met for dep_context=requeueable deps ti=<TaskInstance: crypto_etl_main.transform_data manual__2025-09-19T14:53:41.738222+00:00 [queued]>
[2025-09-19T14:54:00.381+0000] {taskinstance.py:2170} INFO - Starting attempt 1 of 2
[2025-09-19T14:54:00.411+0000] {taskinstance.py:2191} INFO - Executing <Task(PythonOperator): transform_data> on 2025-09-19 14:53:41.738222+00:00
[2025-09-19T14:54:00.424+0000] {standard_task_runner.py:60} INFO - Started process 1430 to run task
[2025-09-19T14:54:00.443+0000] {standard_task_runner.py:87} INFO - Running: ['***', 'tasks', 'run', 'crypto_etl_main', 'transform_data', 'manual__2025-09-19T14:53:41.738222+00:00', '--job-id', '98', '--raw', '--subdir', 'DAGS_FOLDER/crypto_etl_dag.py', '--cfg-path', '/tmp/tmpc5cffsv0']
[2025-09-19T14:54:00.472+0000] {standard_task_runner.py:88} INFO - Job 98: Subtask transform_data
[2025-09-19T14:54:00.575+0000] {task_command.py:423} INFO - Running <TaskInstance: crypto_etl_main.transform_data manual__2025-09-19T14:53:41.738222+00:00 [running]> on host ed735ff6f76b
[2025-09-19T14:54:00.782+0000] {taskinstance.py:2480} INFO - Exporting env vars: AIRFLOW_CTX_DAG_OWNER='data-team' AIRFLOW_CTX_DAG_ID='crypto_etl_main' AIRFLOW_CTX_TASK_ID='transform_data' AIRFLOW_CTX_EXECUTION_DATE='2025-09-19T14:53:41.738222+00:00' AIRFLOW_CTX_TRY_NUMBER='1' AIRFLOW_CTX_DAG_RUN_ID='manual__2025-09-19T14:53:41.738222+00:00'
[2025-09-19T14:54:00.856+0000] {taskinstance.py:2698} ERROR - Task failed with exception
Traceback (most recent call last):
  File "/home/airflow/.local/lib/python3.8/site-packages/airflow/models/taskinstance.py", line 433, in _execute_task
    result = execute_callable(context=context, **execute_callable_kwargs)
  File "/home/airflow/.local/lib/python3.8/site-packages/airflow/operators/python.py", line 199, in execute
    return_value = self.execute_callable()
  File "/home/airflow/.local/lib/python3.8/site-packages/airflow/operators/python.py", line 216, in execute_callable
    return self.python_callable(*self.op_args, **self.op_kwargs)
  File "/opt/airflow/dags/crypto_etl_dag.py", line 173, in transform_and_load_data
    from etl.transform import transform_data
  File "/opt/airflow/dags/etl/transform.py", line 3, in <module>
    from logger_config import logger
ModuleNotFoundError: No module named 'logger_config'
[2025-09-19T14:54:00.890+0000] {taskinstance.py:1138} INFO - Marking task as UP_FOR_RETRY. dag_id=crypto_etl_main, task_id=transform_data, execution_date=20250919T145341, start_date=20250919T145400, end_date=20250919T145400
[2025-09-19T14:54:00.919+0000] {standard_task_runner.py:107} ERROR - Failed to execute job 98 for task transform_data (No module named 'logger_config'; 1430)
[2025-09-19T14:54:00.960+0000] {local_task_job_runner.py:234} INFO - Task exited with return code 1
[2025-09-19T14:54:01.004+0000] {taskinstance.py:3280} INFO - 0 downstream tasks scheduled from follow-on schedule check
