[2025-09-19T14:59:03.205+0000] {taskinstance.py:1956} INFO - Dependencies all met for dep_context=non-requeueable deps ti=<TaskInstance: crypto_etl_main.transform_data manual__2025-09-19T14:53:41.738222+00:00 [queued]>
[2025-09-19T14:59:03.228+0000] {taskinstance.py:1956} INFO - Dependencies all met for dep_context=requeueable deps ti=<TaskInstance: crypto_etl_main.transform_data manual__2025-09-19T14:53:41.738222+00:00 [queued]>
[2025-09-19T14:59:03.229+0000] {taskinstance.py:2170} INFO - Starting attempt 2 of 2
[2025-09-19T14:59:03.269+0000] {taskinstance.py:2191} INFO - Executing <Task(PythonOperator): transform_data> on 2025-09-19 14:53:41.738222+00:00
[2025-09-19T14:59:03.280+0000] {standard_task_runner.py:60} INFO - Started process 1506 to run task
[2025-09-19T14:59:03.287+0000] {standard_task_runner.py:87} INFO - Running: ['***', 'tasks', 'run', 'crypto_etl_main', 'transform_data', 'manual__2025-09-19T14:53:41.738222+00:00', '--job-id', '100', '--raw', '--subdir', 'DAGS_FOLDER/crypto_etl_dag.py', '--cfg-path', '/tmp/tmpraa7c2lk']
[2025-09-19T14:59:03.294+0000] {standard_task_runner.py:88} INFO - Job 100: Subtask transform_data
[2025-09-19T14:59:03.388+0000] {task_command.py:423} INFO - Running <TaskInstance: crypto_etl_main.transform_data manual__2025-09-19T14:53:41.738222+00:00 [running]> on host ed735ff6f76b
[2025-09-19T14:59:03.547+0000] {taskinstance.py:2480} INFO - Exporting env vars: AIRFLOW_CTX_DAG_OWNER='data-team' AIRFLOW_CTX_DAG_ID='crypto_etl_main' AIRFLOW_CTX_TASK_ID='transform_data' AIRFLOW_CTX_EXECUTION_DATE='2025-09-19T14:53:41.738222+00:00' AIRFLOW_CTX_TRY_NUMBER='2' AIRFLOW_CTX_DAG_RUN_ID='manual__2025-09-19T14:53:41.738222+00:00'
[2025-09-19T14:59:03.564+0000] {taskinstance.py:2698} ERROR - Task failed with exception
Traceback (most recent call last):
  File "/home/airflow/.local/lib/python3.8/site-packages/airflow/models/taskinstance.py", line 433, in _execute_task
    result = execute_callable(context=context, **execute_callable_kwargs)
  File "/home/airflow/.local/lib/python3.8/site-packages/airflow/operators/python.py", line 199, in execute
    return_value = self.execute_callable()
  File "/home/airflow/.local/lib/python3.8/site-packages/airflow/operators/python.py", line 216, in execute_callable
    return self.python_callable(*self.op_args, **self.op_kwargs)
  File "/opt/airflow/dags/crypto_etl_dag.py", line 173, in transform_and_load_data
    from etl.transform import transform_data
  File "/opt/airflow/dags/etl/transform.py", line 3, in <module>
    from logger_config import logger
ModuleNotFoundError: No module named 'logger_config'
[2025-09-19T14:59:03.590+0000] {taskinstance.py:1138} INFO - Marking task as FAILED. dag_id=crypto_etl_main, task_id=transform_data, execution_date=20250919T145341, start_date=20250919T145903, end_date=20250919T145903
[2025-09-19T14:59:03.624+0000] {standard_task_runner.py:107} ERROR - Failed to execute job 100 for task transform_data (No module named 'logger_config'; 1506)
[2025-09-19T14:59:03.660+0000] {local_task_job_runner.py:234} INFO - Task exited with return code 1
[2025-09-19T14:59:03.708+0000] {taskinstance.py:3280} INFO - 0 downstream tasks scheduled from follow-on schedule check
