[2025-09-19T13:52:51.113+0000] {taskinstance.py:1956} INFO - Dependencies all met for dep_context=non-requeueable deps ti=<TaskInstance: crypto_etl_main.check_new_files manual__2025-09-19T13:48:13.783367+00:00 [queued]>
[2025-09-19T13:52:51.135+0000] {taskinstance.py:1956} INFO - Dependencies all met for dep_context=requeueable deps ti=<TaskInstance: crypto_etl_main.check_new_files manual__2025-09-19T13:48:13.783367+00:00 [queued]>
[2025-09-19T13:52:51.136+0000] {taskinstance.py:2170} INFO - Starting attempt 1 of 2
[2025-09-19T13:52:51.164+0000] {taskinstance.py:2191} INFO - Executing <Task(BranchPythonOperator): check_new_files> on 2025-09-19 13:48:13.783367+00:00
[2025-09-19T13:52:51.176+0000] {standard_task_runner.py:60} INFO - Started process 497 to run task
[2025-09-19T13:52:51.182+0000] {standard_task_runner.py:87} INFO - Running: ['***', 'tasks', 'run', 'crypto_etl_main', 'check_new_files', 'manual__2025-09-19T13:48:13.783367+00:00', '--job-id', '72', '--raw', '--subdir', 'DAGS_FOLDER/crypto_etl_dag.py', '--cfg-path', '/tmp/tmpb9xxlfwa']
[2025-09-19T13:52:51.191+0000] {standard_task_runner.py:88} INFO - Job 72: Subtask check_new_files
[2025-09-19T13:52:51.276+0000] {task_command.py:423} INFO - Running <TaskInstance: crypto_etl_main.check_new_files manual__2025-09-19T13:48:13.783367+00:00 [running]> on host ed735ff6f76b
[2025-09-19T13:52:51.405+0000] {taskinstance.py:2480} INFO - Exporting env vars: AIRFLOW_CTX_DAG_OWNER='data-team' AIRFLOW_CTX_DAG_ID='crypto_etl_main' AIRFLOW_CTX_TASK_ID='check_new_files' AIRFLOW_CTX_EXECUTION_DATE='2025-09-19T13:48:13.783367+00:00' AIRFLOW_CTX_TRY_NUMBER='1' AIRFLOW_CTX_DAG_RUN_ID='manual__2025-09-19T13:48:13.783367+00:00'
[2025-09-19T13:52:51.595+0000] {log.py:232} WARNING - [2025-09-19 13:52:51,594] INFO - crypto_etl - Listing files from bucket crypto-data with prefix 'raw-data/'
[2025-09-19T13:52:51.594+0000] {extract.py:26} INFO - Listing files from bucket crypto-data with prefix 'raw-data/'
[2025-09-19T13:52:51.619+0000] {log.py:232} WARNING - [2025-09-19 13:52:51,618] INFO - crypto_etl - Found 1 CSV files
[2025-09-19T13:52:51.618+0000] {extract.py:30} INFO - Found 1 CSV files
[2025-09-19T13:52:51.622+0000] {taskinstance.py:2698} ERROR - Task failed with exception
Traceback (most recent call last):
  File "/home/airflow/.local/lib/python3.8/site-packages/airflow/models/taskinstance.py", line 433, in _execute_task
    result = execute_callable(context=context, **execute_callable_kwargs)
  File "/home/airflow/.local/lib/python3.8/site-packages/airflow/operators/python.py", line 233, in execute
    return self.do_branch(context, super().execute(context))
  File "/home/airflow/.local/lib/python3.8/site-packages/airflow/operators/python.py", line 199, in execute
    return_value = self.execute_callable()
  File "/home/airflow/.local/lib/python3.8/site-packages/airflow/operators/python.py", line 216, in execute_callable
    return self.python_callable(*self.op_args, **self.op_kwargs)
  File "/opt/airflow/dags/crypto_etl_dag.py", line 45, in check_new_files
    unprocessed_files = processor.get_unprocessed_files(all_files)
  File "/opt/airflow/dags/etl/file_processor.py", line 16, in get_unprocessed_files
    conn = psycopg2.connect(self.db_conn)
  File "/home/airflow/.local/lib/python3.8/site-packages/psycopg2/__init__.py", line 122, in connect
    conn = _connect(dsn, connection_factory=connection_factory, **kwasync)
psycopg2.OperationalError: connection to server at "localhost" (::1), port 5433 failed: Connection refused
	Is the server running on that host and accepting TCP/IP connections?
connection to server at "localhost" (127.0.0.1), port 5433 failed: Connection refused
	Is the server running on that host and accepting TCP/IP connections?

[2025-09-19T13:52:51.652+0000] {taskinstance.py:1138} INFO - Marking task as UP_FOR_RETRY. dag_id=crypto_etl_main, task_id=check_new_files, execution_date=20250919T134813, start_date=20250919T135251, end_date=20250919T135251
[2025-09-19T13:52:51.675+0000] {standard_task_runner.py:107} ERROR - Failed to execute job 72 for task check_new_files (connection to server at "localhost" (::1), port 5433 failed: Connection refused
	Is the server running on that host and accepting TCP/IP connections?
connection to server at "localhost" (127.0.0.1), port 5433 failed: Connection refused
	Is the server running on that host and accepting TCP/IP connections?
; 497)
[2025-09-19T13:52:51.721+0000] {local_task_job_runner.py:234} INFO - Task exited with return code 1
[2025-09-19T13:52:51.777+0000] {taskinstance.py:3280} INFO - 0 downstream tasks scheduled from follow-on schedule check
