[2025-09-19T14:00:04.941+0000] {taskinstance.py:1956} INFO - Dependencies all met for dep_context=non-requeueable deps ti=<TaskInstance: crypto_etl_main.check_new_files scheduled__2025-09-19T13:45:00+00:00 [queued]>
[2025-09-19T14:00:04.960+0000] {taskinstance.py:1956} INFO - Dependencies all met for dep_context=requeueable deps ti=<TaskInstance: crypto_etl_main.check_new_files scheduled__2025-09-19T13:45:00+00:00 [queued]>
[2025-09-19T14:00:04.961+0000] {taskinstance.py:2170} INFO - Starting attempt 1 of 2
[2025-09-19T14:00:04.987+0000] {taskinstance.py:2191} INFO - Executing <Task(BranchPythonOperator): check_new_files> on 2025-09-19 13:45:00+00:00
[2025-09-19T14:00:04.997+0000] {standard_task_runner.py:60} INFO - Started process 603 to run task
[2025-09-19T14:00:05.006+0000] {standard_task_runner.py:87} INFO - Running: ['***', 'tasks', 'run', 'crypto_etl_main', 'check_new_files', 'scheduled__2025-09-19T13:45:00+00:00', '--job-id', '75', '--raw', '--subdir', 'DAGS_FOLDER/crypto_etl_dag.py', '--cfg-path', '/tmp/tmptflbbirs']
[2025-09-19T14:00:05.014+0000] {standard_task_runner.py:88} INFO - Job 75: Subtask check_new_files
[2025-09-19T14:00:05.116+0000] {task_command.py:423} INFO - Running <TaskInstance: crypto_etl_main.check_new_files scheduled__2025-09-19T13:45:00+00:00 [running]> on host ed735ff6f76b
[2025-09-19T14:00:05.273+0000] {taskinstance.py:2480} INFO - Exporting env vars: AIRFLOW_CTX_DAG_OWNER='data-team' AIRFLOW_CTX_DAG_ID='crypto_etl_main' AIRFLOW_CTX_TASK_ID='check_new_files' AIRFLOW_CTX_EXECUTION_DATE='2025-09-19T13:45:00+00:00' AIRFLOW_CTX_TRY_NUMBER='1' AIRFLOW_CTX_DAG_RUN_ID='scheduled__2025-09-19T13:45:00+00:00'
[2025-09-19T14:00:05.446+0000] {log.py:232} WARNING - [2025-09-19 14:00:05,445] INFO - crypto_etl - Listing files from bucket crypto-data with prefix 'raw-data/'
[2025-09-19T14:00:05.445+0000] {extract.py:26} INFO - Listing files from bucket crypto-data with prefix 'raw-data/'
[2025-09-19T14:00:05.475+0000] {log.py:232} WARNING - [2025-09-19 14:00:05,475] INFO - crypto_etl - Found 1 CSV files
[2025-09-19T14:00:05.475+0000] {extract.py:30} INFO - Found 1 CSV files
[2025-09-19T14:00:05.480+0000] {taskinstance.py:2698} ERROR - Task failed with exception
Traceback (most recent call last):
  File "/home/airflow/.local/lib/python3.8/site-packages/airflow/models/taskinstance.py", line 433, in _execute_task
    result = execute_callable(context=context, **execute_callable_kwargs)
  File "/home/airflow/.local/lib/python3.8/site-packages/airflow/operators/python.py", line 233, in execute
    return self.do_branch(context, super().execute(context))
  File "/home/airflow/.local/lib/python3.8/site-packages/airflow/operators/python.py", line 199, in execute
    return_value = self.execute_callable()
  File "/home/airflow/.local/lib/python3.8/site-packages/airflow/operators/python.py", line 216, in execute_callable
    return self.python_callable(*self.op_args, **self.op_kwargs)
  File "/opt/airflow/dags/crypto_etl_dag.py", line 45, in check_new_files
    unprocessed_files = processor.get_unprocessed_files(all_files)
  File "/opt/airflow/dags/etl/file_processor.py", line 16, in get_unprocessed_files
    conn = psycopg2.connect(self.db_conn)
  File "/home/airflow/.local/lib/python3.8/site-packages/psycopg2/__init__.py", line 122, in connect
    conn = _connect(dsn, connection_factory=connection_factory, **kwasync)
psycopg2.OperationalError: connection to server at "localhost" (::1), port 5433 failed: Connection refused
	Is the server running on that host and accepting TCP/IP connections?
connection to server at "localhost" (127.0.0.1), port 5433 failed: Connection refused
	Is the server running on that host and accepting TCP/IP connections?

[2025-09-19T14:00:05.514+0000] {taskinstance.py:1138} INFO - Marking task as UP_FOR_RETRY. dag_id=crypto_etl_main, task_id=check_new_files, execution_date=20250919T134500, start_date=20250919T140004, end_date=20250919T140005
[2025-09-19T14:00:05.538+0000] {standard_task_runner.py:107} ERROR - Failed to execute job 75 for task check_new_files (connection to server at "localhost" (::1), port 5433 failed: Connection refused
	Is the server running on that host and accepting TCP/IP connections?
connection to server at "localhost" (127.0.0.1), port 5433 failed: Connection refused
	Is the server running on that host and accepting TCP/IP connections?
; 603)
[2025-09-19T14:00:05.579+0000] {local_task_job_runner.py:234} INFO - Task exited with return code 1
[2025-09-19T14:00:05.634+0000] {taskinstance.py:3280} INFO - 0 downstream tasks scheduled from follow-on schedule check
