[2025-09-19T13:42:19.831+0000] {taskinstance.py:1956} INFO - Dependencies all met for dep_context=non-requeueable deps ti=<TaskInstance: crypto_etl_main.check_new_files manual__2025-09-19T13:41:49.606313+00:00 [queued]>
[2025-09-19T13:42:19.847+0000] {taskinstance.py:1956} INFO - Dependencies all met for dep_context=requeueable deps ti=<TaskInstance: crypto_etl_main.check_new_files manual__2025-09-19T13:41:49.606313+00:00 [queued]>
[2025-09-19T13:42:19.848+0000] {taskinstance.py:2170} INFO - Starting attempt 1 of 2
[2025-09-19T13:42:19.876+0000] {taskinstance.py:2191} INFO - Executing <Task(BranchPythonOperator): check_new_files> on 2025-09-19 13:41:49.606313+00:00
[2025-09-19T13:42:19.885+0000] {standard_task_runner.py:60} INFO - Started process 336 to run task
[2025-09-19T13:42:19.890+0000] {standard_task_runner.py:87} INFO - Running: ['***', 'tasks', 'run', 'crypto_etl_main', 'check_new_files', 'manual__2025-09-19T13:41:49.606313+00:00', '--job-id', '69', '--raw', '--subdir', 'DAGS_FOLDER/crypto_etl_dag.py', '--cfg-path', '/tmp/tmplhf7v6fc']
[2025-09-19T13:42:19.895+0000] {standard_task_runner.py:88} INFO - Job 69: Subtask check_new_files
[2025-09-19T13:42:19.980+0000] {task_command.py:423} INFO - Running <TaskInstance: crypto_etl_main.check_new_files manual__2025-09-19T13:41:49.606313+00:00 [running]> on host ed735ff6f76b
[2025-09-19T13:42:20.119+0000] {taskinstance.py:2480} INFO - Exporting env vars: AIRFLOW_CTX_DAG_OWNER='data-team' AIRFLOW_CTX_DAG_ID='crypto_etl_main' AIRFLOW_CTX_TASK_ID='check_new_files' AIRFLOW_CTX_EXECUTION_DATE='2025-09-19T13:41:49.606313+00:00' AIRFLOW_CTX_TRY_NUMBER='1' AIRFLOW_CTX_DAG_RUN_ID='manual__2025-09-19T13:41:49.606313+00:00'
[2025-09-19T13:42:20.275+0000] {taskinstance.py:2698} ERROR - Task failed with exception
Traceback (most recent call last):
  File "/home/airflow/.local/lib/python3.8/site-packages/airflow/models/taskinstance.py", line 433, in _execute_task
    result = execute_callable(context=context, **execute_callable_kwargs)
  File "/home/airflow/.local/lib/python3.8/site-packages/airflow/operators/python.py", line 233, in execute
    return self.do_branch(context, super().execute(context))
  File "/home/airflow/.local/lib/python3.8/site-packages/airflow/operators/python.py", line 199, in execute
    return_value = self.execute_callable()
  File "/home/airflow/.local/lib/python3.8/site-packages/airflow/operators/python.py", line 216, in execute_callable
    return self.python_callable(*self.op_args, **self.op_kwargs)
  File "/opt/airflow/dags/crypto_etl_dag.py", line 34, in check_new_files
    from etl.extract import MinioExtractor
  File "/opt/airflow/dags/etl/extract.py", line 8, in <module>
    from logger_config import logger  # use configured logger
ModuleNotFoundError: No module named 'logger_config'
[2025-09-19T13:42:20.301+0000] {taskinstance.py:1138} INFO - Marking task as UP_FOR_RETRY. dag_id=crypto_etl_main, task_id=check_new_files, execution_date=20250919T134149, start_date=20250919T134219, end_date=20250919T134220
[2025-09-19T13:42:20.327+0000] {standard_task_runner.py:107} ERROR - Failed to execute job 69 for task check_new_files (No module named 'logger_config'; 336)
[2025-09-19T13:42:20.344+0000] {local_task_job_runner.py:234} INFO - Task exited with return code 1
[2025-09-19T13:42:20.391+0000] {taskinstance.py:3280} INFO - 0 downstream tasks scheduled from follow-on schedule check
