[2025-09-19T11:36:44.204+0000] {taskinstance.py:1956} INFO - Dependencies all met for dep_context=non-requeueable deps ti=<TaskInstance: crypto_data_generator.generate_and_upload_crypto_data manual__2025-09-19T11:26:33.959821+00:00 [queued]>
[2025-09-19T11:36:44.219+0000] {taskinstance.py:1956} INFO - Dependencies all met for dep_context=requeueable deps ti=<TaskInstance: crypto_data_generator.generate_and_upload_crypto_data manual__2025-09-19T11:26:33.959821+00:00 [queued]>
[2025-09-19T11:36:44.220+0000] {taskinstance.py:2170} INFO - Starting attempt 3 of 3
[2025-09-19T11:36:44.243+0000] {taskinstance.py:2191} INFO - Executing <Task(PythonOperator): generate_and_upload_crypto_data> on 2025-09-19 11:26:33.959821+00:00
[2025-09-19T11:36:44.252+0000] {standard_task_runner.py:60} INFO - Started process 298 to run task
[2025-09-19T11:36:44.258+0000] {standard_task_runner.py:87} INFO - Running: ['***', 'tasks', 'run', 'crypto_data_generator', 'generate_and_upload_crypto_data', 'manual__2025-09-19T11:26:33.959821+00:00', '--job-id', '38', '--raw', '--subdir', 'DAGS_FOLDER/crypto_data_generator_dag.py', '--cfg-path', '/tmp/tmpvgfltpuk']
[2025-09-19T11:36:44.260+0000] {standard_task_runner.py:88} INFO - Job 38: Subtask generate_and_upload_crypto_data
[2025-09-19T11:36:44.343+0000] {task_command.py:423} INFO - Running <TaskInstance: crypto_data_generator.generate_and_upload_crypto_data manual__2025-09-19T11:26:33.959821+00:00 [running]> on host ece681799ab2
[2025-09-19T11:36:44.467+0000] {taskinstance.py:2480} INFO - Exporting env vars: AIRFLOW_CTX_DAG_OWNER='data-team' AIRFLOW_CTX_DAG_ID='crypto_data_generator' AIRFLOW_CTX_TASK_ID='generate_and_upload_crypto_data' AIRFLOW_CTX_EXECUTION_DATE='2025-09-19T11:26:33.959821+00:00' AIRFLOW_CTX_TRY_NUMBER='3' AIRFLOW_CTX_DAG_RUN_ID='manual__2025-09-19T11:26:33.959821+00:00'
[2025-09-19T11:36:44.470+0000] {warnings.py:109} WARNING - /home/***/.local/lib/python3.8/site-packages/***/utils/context.py:315: AirflowContextDeprecationWarning: Accessing 'execution_date' from the template is deprecated and will be removed in a future version. Please use 'data_interval_start' or 'logical_date' instead.
  warnings.warn(_create_deprecation_warning(k, replacements))

[2025-09-19T11:36:44.472+0000] {logging_mixin.py:188} INFO - Generated /tmp/crypto_data_20250919_11.csv
[2025-09-19T11:36:44.484+0000] {logging_mixin.py:188} INFO - Failed to upload /tmp/crypto_data_20250919_11.csv: S3 operation failed; code: SignatureDoesNotMatch, message: The request signature we calculated does not match the signature you provided. Check your key and signing method., resource: /crypto-data, request_id: 1866ABFC430C1302, host_id: dd9025bab4ad464b049177c95eb6ebf374d3b3fd1af9251148b658df7ac2e3e8, bucket_name: crypto-data
[2025-09-19T11:36:44.485+0000] {taskinstance.py:2698} ERROR - Task failed with exception
Traceback (most recent call last):
  File "/home/airflow/.local/lib/python3.8/site-packages/airflow/models/taskinstance.py", line 433, in _execute_task
    result = execute_callable(context=context, **execute_callable_kwargs)
  File "/home/airflow/.local/lib/python3.8/site-packages/airflow/operators/python.py", line 199, in execute
    return_value = self.execute_callable()
  File "/home/airflow/.local/lib/python3.8/site-packages/airflow/operators/python.py", line 216, in execute_callable
    return self.python_callable(*self.op_args, **self.op_kwargs)
  File "/opt/airflow/dags/crypto_data_generator_dag.py", line 69, in generate_and_upload_data
    upload_to_organized_path(local_temp_path, f"{folder_path}/{filename}")
  File "/opt/airflow/dags/crypto_data_generator_dag.py", line 47, in upload_to_organized_path
    if not client.bucket_exists(bucket_name):
  File "/home/airflow/.local/lib/python3.8/site-packages/minio/api.py", line 696, in bucket_exists
    self._execute("HEAD", bucket_name)
  File "/home/airflow/.local/lib/python3.8/site-packages/minio/api.py", line 437, in _execute
    region = self._get_region(bucket_name)
  File "/home/airflow/.local/lib/python3.8/site-packages/minio/api.py", line 494, in _get_region
    response = self._url_open(
  File "/home/airflow/.local/lib/python3.8/site-packages/minio/api.py", line 423, in _url_open
    raise response_error
minio.error.S3Error: S3 operation failed; code: SignatureDoesNotMatch, message: The request signature we calculated does not match the signature you provided. Check your key and signing method., resource: /crypto-data, request_id: 1866ABFC430C1302, host_id: dd9025bab4ad464b049177c95eb6ebf374d3b3fd1af9251148b658df7ac2e3e8, bucket_name: crypto-data
[2025-09-19T11:36:44.505+0000] {taskinstance.py:1138} INFO - Marking task as FAILED. dag_id=crypto_data_generator, task_id=generate_and_upload_crypto_data, execution_date=20250919T112633, start_date=20250919T113644, end_date=20250919T113644
[2025-09-19T11:36:44.524+0000] {standard_task_runner.py:107} ERROR - Failed to execute job 38 for task generate_and_upload_crypto_data (S3 operation failed; code: SignatureDoesNotMatch, message: The request signature we calculated does not match the signature you provided. Check your key and signing method., resource: /crypto-data, request_id: 1866ABFC430C1302, host_id: dd9025bab4ad464b049177c95eb6ebf374d3b3fd1af9251148b658df7ac2e3e8, bucket_name: crypto-data; 298)
[2025-09-19T11:36:44.551+0000] {local_task_job_runner.py:234} INFO - Task exited with return code 1
[2025-09-19T11:36:44.581+0000] {taskinstance.py:3280} INFO - 0 downstream tasks scheduled from follow-on schedule check
