[2025-09-19T14:21:03.663+0000] {taskinstance.py:1956} INFO - Dependencies all met for dep_context=non-requeueable deps ti=<TaskInstance: crypto_etl_main.validate_files manual__2025-09-19T14:15:51.774576+00:00 [queued]>
[2025-09-19T14:21:03.684+0000] {taskinstance.py:1956} INFO - Dependencies all met for dep_context=requeueable deps ti=<TaskInstance: crypto_etl_main.validate_files manual__2025-09-19T14:15:51.774576+00:00 [queued]>
[2025-09-19T14:21:03.685+0000] {taskinstance.py:2170} INFO - Starting attempt 2 of 2
[2025-09-19T14:21:03.722+0000] {taskinstance.py:2191} INFO - Executing <Task(BranchPythonOperator): validate_files> on 2025-09-19 14:15:51.774576+00:00
[2025-09-19T14:21:03.732+0000] {standard_task_runner.py:60} INFO - Started process 922 to run task
[2025-09-19T14:21:03.738+0000] {standard_task_runner.py:87} INFO - Running: ['***', 'tasks', 'run', 'crypto_etl_main', 'validate_files', 'manual__2025-09-19T14:15:51.774576+00:00', '--job-id', '82', '--raw', '--subdir', 'DAGS_FOLDER/crypto_etl_dag.py', '--cfg-path', '/tmp/tmpp5h7e1ow']
[2025-09-19T14:21:03.743+0000] {standard_task_runner.py:88} INFO - Job 82: Subtask validate_files
[2025-09-19T14:21:03.834+0000] {task_command.py:423} INFO - Running <TaskInstance: crypto_etl_main.validate_files manual__2025-09-19T14:15:51.774576+00:00 [running]> on host ed735ff6f76b
[2025-09-19T14:21:04.030+0000] {taskinstance.py:2480} INFO - Exporting env vars: AIRFLOW_CTX_DAG_OWNER='data-team' AIRFLOW_CTX_DAG_ID='crypto_etl_main' AIRFLOW_CTX_TASK_ID='validate_files' AIRFLOW_CTX_EXECUTION_DATE='2025-09-19T14:15:51.774576+00:00' AIRFLOW_CTX_TRY_NUMBER='2' AIRFLOW_CTX_DAG_RUN_ID='manual__2025-09-19T14:15:51.774576+00:00'
[2025-09-19T14:21:04.260+0000] {taskinstance.py:2698} ERROR - Task failed with exception
Traceback (most recent call last):
  File "/home/airflow/.local/lib/python3.8/site-packages/airflow/models/taskinstance.py", line 433, in _execute_task
    result = execute_callable(context=context, **execute_callable_kwargs)
  File "/home/airflow/.local/lib/python3.8/site-packages/airflow/operators/python.py", line 233, in execute
    return self.do_branch(context, super().execute(context))
  File "/home/airflow/.local/lib/python3.8/site-packages/airflow/operators/python.py", line 199, in execute
    return_value = self.execute_callable()
  File "/home/airflow/.local/lib/python3.8/site-packages/airflow/operators/python.py", line 216, in execute_callable
    return self.python_callable(*self.op_args, **self.op_kwargs)
  File "/opt/airflow/dags/crypto_etl_dag.py", line 61, in validate_file_structure
    from etl.data_quality import DataQualityChecker
  File "/opt/airflow/dags/etl/data_quality.py", line 3, in <module>
    from logger_config import logger
ModuleNotFoundError: No module named 'logger_config'
[2025-09-19T14:21:04.287+0000] {taskinstance.py:1138} INFO - Marking task as FAILED. dag_id=crypto_etl_main, task_id=validate_files, execution_date=20250919T141551, start_date=20250919T142103, end_date=20250919T142104
[2025-09-19T14:21:04.314+0000] {standard_task_runner.py:107} ERROR - Failed to execute job 82 for task validate_files (No module named 'logger_config'; 922)
[2025-09-19T14:21:04.353+0000] {local_task_job_runner.py:234} INFO - Task exited with return code 1
[2025-09-19T14:21:04.436+0000] {taskinstance.py:3280} INFO - 0 downstream tasks scheduled from follow-on schedule check
